Workbook

Sheet Coves Data
A1: Category | B1: Deal Period Total | C1: Monthly Avg. | D1: % of Gross Rev
A2: Total Revenue | B2: 27434830937 | C2: 228623591 | D2: 100.0%
A3: Cove Platform Fee | B3: -682874953 | C3: -5690625 | D3: 2.5%
A4: OTA Cost | B4: -2548806397 | C4: -21240053 | D4: 9.3%
A5: Net Revenue | B5: 24203149587 | C5: 201692913 | D5: 88.2%
A6: OPEX | B6: -8119692836 | C6: -67664107 | D6: 29.6%
A7: Gross Operating Profit | B7: 16083456751 | C7: 134028806 | D7: 58.6%
A8: Cove Incentive Fee | B8: -2901793688 | C8: -24181614 | D8: 10.6%
A9: Net Operating Profit | B9: 13181663062 | C9: 109847192 | D9: 48.0%
A10: Owner Share | B10: 13219282358 | C10: 110160686 | D10: 48.2%
A13: Category | B13: Y0 | C13: Y1 | D13: Y2 | E13: Y3 | F13: Y4 | G13: Y5 | H13: Y6 | I13: Y7 | J13: Y8 | K13: Y9 | L13: Y10
A14: Landlord Investment | B14: -7000000000
A15: Owner NOI | C15: 963112494 | D15: 1202297616 | E15: 1288696733 | F15: 1271176930 | G15: 1348104787 | H15: 1331830343 | I15: 1430647315 | J15: 1410331110 | K15: 1495710294 | L15: 1477374736
A16: Project Cash Flow | B16: =B14 -> -7000000000 | C16: 963112494 | D16: 1202297616 | E16: 1288696733 | F16: 1271176930 | G16: 1348104787 | H16: 1331830343 | I16: 1430647315 | J16: 1410331110 | K16: 1495710294 | L16: 1477374736
A17: Net Cash Flow | B17: =B16 -> -7000000000 | C17: =B16+C16 -> -6036887506 | D17: =C17+D16 -> -4834589890 | E17: =D17+E16 -> -3545893157 | F17: =E17+F16 -> -2274716227 | G17: =F17+G16 -> -926611440 | H17: =G17+H16 -> 405218903 | I17: =H17+I16 -> 1835866218 | J17: =I17+J16 -> 3246197328 | K17: =J17+K16 -> 4741907622 | L17: =K17+L16 -> 6219282358
A20: Metric | B20: Value
A21: Project Unlevered IRR | B21: 12.70%
A22: Payback period | B22: 5.75 Years
A23: 2nd Year Yield-on-Cost Ratio | B23: 17.18%

Sheet Financial Model Original
A1: Project Assumptions | C1: Values
A2: Investment
A3: Initial Investment (Landlord) | C3: 7000000000
A5: Operations | E5: 19 rooms @ 85%
A6: Number of Rooms | C6: 38 | E6: 19 rooms daily rate at 350k @65%
A7: Average Monthly Rent per Room | C7: 4600000
A9: Growth & Inflation
A10: Annual Rent Growth | C10: 0.03
A11: Annual OPEX Growth | C11: 0.025
A13: Occupancy Ramp-Up
A14: Year 1 Occupancy | C14: 0.85
A15: Stabilized Occupancy (Y2+) | C15: 0.92
A17: Fees & Costs (% of Total Revenue)
A18: Cove Platform Fee | C18: 0.025
A19: OTA Cost | C19: 0.093
A20: OPEX (% of Net Revenue) | C20: 0.296
A21: Cove Incentive Fee (% of GOP) | C21: 0.18
A24: Line Item | B24: Year 0 | C24: Year 1 | D24: Year 2 | E24: Year 3 | F24: Year 4 | G24: Year 5 | H24: Year 6 | I24: Year 7 | J24: Year 8 | K24: Year 9 | L24: Year 10
A25: Revenue
A26: Gross Potential Rent | C26: =$C$6*$C$7*12 -> 2097600000 | D26: =C26*(1+$C$10) -> 2160528000 | E26: =D26*(1+$C$10) -> 2225343840 | F26: =E26*(1+$C$10) -> 2.2921042e+09 | G26: =F26*(1+$C$10) -> 2.3608673e+09 | H26: =G26*(1+$C$10) -> 2.4316933e+09 | I26: =H26*(1+$C$10) -> 2.5046441e+09 | J26: =I26*(1+$C$10) -> 2.5797834e+09 | K26: =J26*(1+$C$10) -> 2.6571769e+09 | L26: =K26*(1+$C$10) -> 2.7368922e+09
A27: Vacancy Loss | C27: =C26*(1-$C$14) -> 3.1464e+08 | D27: =D26*(1-$C$15) -> 1.7284224e+08 | E27: =E26*(1-$C$15) -> 1.7802751e+08 | F27: =F26*(1-$C$15) -> 1.8336833e+08 | G27: =G26*(1-$C$15) -> 1.8886938e+08 | H27: =H26*(1-$C$15) -> 1.9453546e+08 | I27: =I26*(1-$C$15) -> 2.0037153e+08 | J27: =J26*(1-$C$15) -> 2.0638267e+08 | K27: =K26*(1-$C$15) -> 2.1257415e+08 | L27: =L26*(1-$C$15) -> 2.1895138e+08
A28: Total Revenue | C28: =C26-C27 -> 1782960000 | D28: =D26-D27 -> 1987685760 | E28: =E26-E27 -> 2.0473163e+09 | F28: =F26-F27 -> 2.1087358e+09 | G28: =G26-G27 -> 2.1719979e+09 | H28: =H26-H27 -> 2.2371578e+09 | I28: =I26-I27 -> 2.3042726e+09 | J28: =J26-J27 -> 2.3734007e+09 | ... L28: =L26-L27 -> 2.5179409e+09
A29: Deductions
A30: Cove Platform Fee | C30: =-C28*$C$18 -> -44574000 | D30: =-D28*$C$18 -> -49692144 | E30: =-E28*$C$18 -> -51182908 | F30: =-F28*$C$18 -> -52718396 | G30: =-G28*$C$18 -> -54299947 | H30: =-H28*$C$18 -> -55928946 | I30: =-I28*$C$18 -> -57606814 | J30: =-J28*$C$18 -> -59335019 | ... L30: =-L28*$C$18 -> -62948521
A31: OTA Cost | C31: =-C28*$C$19 -> -165815280 | D31: =-D28*$C$19 -> -1.8485478e+08 | E31: =-E28*$C$19 -> -1.9040042e+08 | F31: =-F28*$C$19 -> -1.9611243e+08 | G31: =-G28*$C$19 -> -2.019958e+08 | H31: =-H28*$C$19 -> -2.0805568e+08 | I31: =-I28*$C$19 -> -2.1429735e+08 | J31: =-J28*$C$19 -> -2.2072627e+08 | ... L31: =-L28*$C$19 -> -2.341685e+08
A32: Net Revenue | C32: =SUM(C28:C31) -> 1572570720 | D32: =SUM(D28:D31) -> 1.7531388e+09 | E32: =SUM(E28:E31) -> 1.805733e+09 | F32: =SUM(F28:F31) -> 1.859905e+09 | G32: =SUM(G28:G31) -> 1.9157021e+09 | H32: =SUM(H28:H31) -> 1.9731732e+09 | I32: =SUM(I28:I31) -> 2.0323684e+09 | J32: =SUM(J28:J31) -> 2.0933395e+09 | ... L32: =SUM(L28:L31) -> 2.2208238e+09
A33: Operating Expenses (OPEX) | C33: =-C28*$C$20 -> -527756160 | D33: =C33*(1+$C$11) -> -540950064 | E33: =D33*(1+$C$11) -> -5.5447382e+08 | F33: =E33*(1+$C$11) -> -5.6833566e+08 | G33: =F33*(1+$C$11) -> -5.8254405e+08 | H33: =G33*(1+$C$11) -> -5.9710765e+08 | I33: =H33*(1+$C$11) -> -6.1203535e+08 | J33: =I33*(1+$C$11) -> -6.2733623e+08 | K33: =J33*(1+$C$11) -> -6.4301963e+08 | L33: =K33*(1+$C$11) -> -6.5909513e+08
A34: Gross Operating Profit (GOP) | C34: =SUM(C32:C33) -> 1044814560 | D34: =SUM(D32:D33) -> 1.2121888e+09 | E34: =SUM(E32:E33) -> 1.2512592e+09 | F34: =SUM(F32:F33) -> 1.2915693e+09 | G34: =SUM(G32:G33) -> 1.3331581e+09 | H34: =SUM(H32:H33) -> 1.3760656e+09 | I34: =SUM(I32:I33) -> 1.4203331e+09 | J34: =SUM(J32:J33) -> 1.4660032e+09 | ... L34: =SUM(L32:L33) -> 1.5617287e+09
A35: Cove Incentive Fee | C35: =-C34*$C$21 -> -1.8806662e+08 | D35: =-D34*$C$21 -> -2.1819398e+08 | E35: =-E34*$C$21 -> -2.2522665e+08 | F35: =-F34*$C$21 -> -2.3248248e+08 | G35: =-G34*$C$21 -> -2.3996846e+08 | H35: =-H34*$C$21 -> -2.476918e+08 | I35: =-I34*$C$21 -> -2.5565995e+08 | J35: =-J34*$C$21 -> -2.6388058e+08 | ... L35: =-L34*$C$21 -> -2.8111117e+08
A36: Owner Share (NOI) | C36: =SUM(C34:C35) -> 8.5674794e+08 | D36: =SUM(D34:D35) -> 9.939948e+08 | E36: =SUM(E34:E35) -> 1.0260325e+09 | F36: =SUM(F34:F35) -> 1.0590869e+09 | G36: =SUM(G34:G35) -> 1.0931896e+09 | H36: =SUM(H34:H35) -> 1.1283738e+09 | I36: =SUM(I34:I35) -> 1.1646731e+09 | J36: =SUM(J34:J35) -> 1.2021226e+09 | ... L36: =SUM(L34:L35) -> 1.2806175e+09
A37: Project Cash Flow | B37: =-$C$3 -> -7000000000 | C37: =C36 -> 8.5674794e+08 | D37: =D36 -> 9.939948e+08 | E37: =E36 -> 1.0260325e+09 | F37: =F36 -> 1.0590869e+09 | G37: =G36 -> 1.0931896e+09 | H37: =H36 -> 1.1283738e+09 | I37: =I36 -> 1.1646731e+09 | J37: =J36 -> 1.2021226e+09 | ... L37: =L36 -> 1.2806175e+09
A38: Cumulative Cash Flow | B38: =B37 -> -7000000000 | C38: =B38+C37 -> -6.1432521e+09 | D38: =C38+D37 -> -5.1492573e+09 | E38: =D38+E37 -> -4.1232247e+09 | F38: =E38+F37 -> -3.0641379e+09 | G38: =F38+G37 -> -1.9709482e+09 | H38: =G38+H37 -> -8.4257448e+08 | I38: =H38+I37 -> 3.2209863e+08 | J38: =I38+J37 -> 1.5242213e+09 | ... L38: =K38+L37 -> 4.0455972e+09
A40: Cash Flow for IRR | B40: =-$C$3 -> -7000000000 | J40: Occupancy Break-Even
A41: Year 1 | B41: =C37 -> 8.5674794e+08 | J41: Break even no of rooms | K41: =-((D30+D31+D33+D35)/12)/C7 -> 18.001648
A42: Year 2 | B42: =D$37 -> 9.939948e+08 | J42: Break even occupancy % | K42: =K41/C6 -> 0.47372758
A43: Year 3 | B43: =E$37 -> 1.0260325e+09 | J43: We need to rent 18 rooms in order to cover all the monthly costs
A44: Year 4 | B44: =F$37 -> 1.0590869e+09
A45: Year 5 | B45: =G$37 -> 1.0931896e+09
A46: Year 6 | B46: =H$37 -> 1.1283738e+09
A47: Year 7 | B47: =I$37 -> 1.1646731e+09
...

Sheet Medium case - Main Dashboard
A1: Project Kemang Cove Feasibility based on new data
A2: Initial Investment | C2: =Assumptions!C3 -> 6000000000 | E2: Cost Item | F2: Year 1 | G2: Year 2 | H2: Year 3 | I2: Year 4 | J2: Year 5 | K2: Year 6 | L2: Year 7 | M2: Year 8 | N2: Year 9 | O2: Year 10
A3: Total Rooms | C3: =Assumptions!C4 -> 40 | E3: Building Electricity | F3: ='Opex Schedule'!B2 -> 120000000 | G3: ='Opex Schedule'!C2 -> 122400000 | H3: ='Opex Schedule'!D2 -> 124848000 | I3: ='Opex Schedule'!E2 -> 127344960 | J3: ='Opex Schedule'!F2 -> 1.2989186e+08 | K3: ='Opex Schedule'!G2 -> 1.324897e+08 | L3: ='Opex Schedule'!H2 -> 1.3513949e+08 | M3: ='Opex Schedule'!I2 -> 1.3784228e+08 | ... O3: ='Opex Schedule'!K2 -> 1.4341111e+08
E4: Subscriptions | F4: ='Opex Schedule'!B3 -> 36000000 | G4: ='Opex Schedule'!C3 -> 36720000 | H4: ='Opex Schedule'!D3 -> 37454400 | I4: ='Opex Schedule'!E3 -> 38203488 | J4: ='Opex Schedule'!F3 -> 38967558 | K4: ='Opex Schedule'!G3 -> 39746909 | L4: ='Opex Schedule'!H3 -> 40541847 | M4: ='Opex Schedule'!I3 -> 41352684 | ... O4: ='Opex Schedule'!K3 -> 43023332
A5: Standard Rooms (16.5 sqm - 31 units) | C5: =Assumptions!C6 -> 31 | E5: AC Servicing | F5: ='Opex Schedule'!B4 -> 18000000 | G5: ='Opex Schedule'!C4 -> 18360000 | H5: ='Opex Schedule'!D4 -> 18727200 | I5: ='Opex Schedule'!E4 -> 19101744 | J5: ='Opex Schedule'!F4 -> 19483779 | K5: ='Opex Schedule'!G4 -> 19873454 | L5: ='Opex Schedule'!H4 -> 20270924 | M5: ='Opex Schedule'!I4 -> 20676342 | ... O5: ='Opex Schedule'!K4 -> 21511666
A6: Superior + Montly rate | C6: =Assumptions!C7 -> 4600000 | E6: MEP Maintenance | F6: ='Opex Schedule'!B5 -> 36000000 | G6: ='Opex Schedule'!C5 -> 36720000 | H6: ='Opex Schedule'!D5 -> 37454400 | I6: ='Opex Schedule'!E5 -> 38203488 | J6: ='Opex Schedule'!F5 -> 38967558 | K6: ='Opex Schedule'!G5 -> 39746909 | L6: ='Opex Schedule'!H5 -> 40541847 | M6: ='Opex Schedule'!I5 -> 41352684 | ... O6: ='Opex Schedule'!K5 -> 43023332
A7: Superior + Daily rate | C7: =Assumptions!C8 -> 460000 | E7: Neighborhood Fees | F7: ='Opex Schedule'!B6 -> 7200000 | G7: ='Opex Schedule'!C6 -> 7344000 | H7: ='Opex Schedule'!D6 -> 7490880 | I7: ='Opex Schedule'!E6 -> 7640697.6 | J7: ='Opex Schedule'!F6 -> 7793511.6 | K7: ='Opex Schedule'!G6 -> 7949381.8 | L7: ='Opex Schedule'!H6 -> 8108369.4 | M7: ='Opex Schedule'!I6 -> 8270536.8 | ... O7: ='Opex Schedule'!K6 -> 8604666.5
E8: Handyman Service Costs | F8: ='Opex Schedule'!B7 -> 24000000 | G8: ='Opex Schedule'!C7 -> 24480000 | H8: ='Opex Schedule'!D7 -> 24969600 | I8: ='Opex Schedule'!E7 -> 25468992 | J8: ='Opex Schedule'!F7 -> 25978372 | K8: ='Opex Schedule'!G7 -> 26497939 | L8: ='Opex Schedule'!H7 -> 27027898 | M8: ='Opex Schedule'!I7 -> 27568456 | ... O8: ='Opex Schedule'!K7 -> 28682222
A9: Deluxe Rooms (20.4 sqm - 3 units) | C9: =Assumptions!C10 -> 3 | E9: Payroll | F9: ='Opex Schedule'!B8 -> 450000000 | G9: ='Opex Schedule'!C8 -> 492375000 | H9: ='Opex Schedule'!D8 -> 497298750 | I9: ='Opex Schedule'!E8 -> 5.0227174e+08 | J9: ='Opex Schedule'!F8 -> 5.0729445e+08 | K9: ='Opex Schedule'!G8 -> 5.123674e+08 | L9: ='Opex Schedule'!H8 -> 5.1749107e+08 | M9: ='Opex Schedule'!I8 -> 5.2266598e+08 | ... O9: ='Opex Schedule'!K8 -> 5.3317157e+08
A10: Deluxe Monthly Rate | C10: =Assumptions!C11 -> 5000000 | E10: Fixed Costs - Subtotal | F10: =SUM(F3:F9) -> 691200000 | G10: =SUM(G3:G9) -> 738399000 | H10: =SUM(H3:H9) -> 748243230 | I10: =SUM(I3:I9) -> 7.5823511e+08 | J10: =SUM(J3:J9) -> 7.6837709e+08 | K10: =SUM(K3:K9) -> 7.7867169e+08 | L10: =SUM(L3:L9) -> 7.8912145e+08 | M10: =SUM(M3:M9) -> 7.9972897e+08 | ... O10: =SUM(O3:O9) -> 8.214279e+08
A11: Deluxe Daily Rate | C11: =Assumptions!C12 -> 500000
E12: Water Bill | F12: ='Opex Schedule'!B10 -> 30000000 | G12: ='Opex Schedule'!C10 -> 30000000 | H12: ='Opex Schedule'!D10 -> 30000000 | I12: ='Opex Schedule'!E10 -> 30000000 | J12: ='Opex Schedule'!F10 -> 30000000 | K12: ='Opex Schedule'!G10 -> 30000000 | L12: ='Opex Schedule'!H10 -> 30000000 | M12: ='Opex Schedule'!I10 -> 30000000 | ... O12: ='Opex Schedule'!K10 -> 30000000
A13: Premium 1 Rooms (26.4 sqm - 2 units) | C13: =Assumptions!C14 -> 2 | E13: STS Amenities | F13: ='Opex Schedule'!B11 -> 12000000 | G13: ='Opex Schedule'!C11 -> 12240000 | H13: ='Opex Schedule'!D11 -> 12484800 | I13: ='Opex Schedule'!E11 -> 12734496 | J13: ='Opex Schedule'!F11 -> 12989186 | K13: ='Opex Schedule'!G11 -> 13248970 | L13: ='Opex Schedule'!H11 -> 13513949 | M13: ='Opex Schedule'!I11 -> 13784228 | ... O13: ='Opex Schedule'!K11 -> 14341111
A14: Premium 1 Montly rate | C14: =Assumptions!C15 -> 5900000
A15: Premium 1 Daily rate | C15: =Assumptions!C16 -> 590000 | E15: Cleaning | F15: ='Opex Schedule'!B12 -> 12000000 | G15: ='Opex Schedule'!C12 -> 12240000 | H15: ='Opex Schedule'!D12 -> 12484800 | I15: ='Opex Schedule'!E12 -> 12734496 | J15: ='Opex Schedule'!F12 -> 12989186 | K15: ='Opex Schedule'!G12 -> 13248970 | L15: ='Opex Schedule'!H12 -> 13513949 | M15: ='Opex Schedule'!I12 -> 13784228 | ... O15: ='Opex Schedule'!K12 -> 14341111
E16: Variable Costs - Subtotal | F16: =SUM(F11:F15) -> 54000000 | G16: =SUM(G11:G15) -> 54480000 | H16: =SUM(H11:H15) -> 54969600 | I16: =SUM(I11:I15) -> 55468992 | J16: =SUM(J11:J15) -> 55978372 | K16: =SUM(K11:K15) -> 56497939 | L16: =SUM(L11:L15) -> 57027898 | M16: =SUM(M11:M15) -> 57568456 | ... O16: =SUM(O11:O15) -> 58682222
A17: Premium 2 Rooms (22.4 sqm - 4 units) | C17: =Assumptions!C18 -> 4 | E17: Total Operating Expenses | F17: =F10+F16 -> 745200000 | G17: =G10+G16 -> 792879000 | H17: =H10+H16 -> 803212830 | I17: =I10+I16 -> 8.137041e+08 | J17: =J10+J16 -> 8.2435546e+08 | K17: =K10+K16 -> 8.3516963e+08 | L17: =L10+L16 -> 8.4614935e+08 | M17: =M10+M16 -> 8.5729742e+08 | ... O17: =O10+O16 -> 8.8011012e+08
A18: Premium 2 Monthly rate | C18: =Assumptions!C19 -> 5500000
A19: Premium 2 Daily rate | C19: =Assumptions!C20 -> 550000 | E19: Line Item | F19: Year 0 | G19: Year 1 | H19: Year 2 | I19: Year 3 | J19: Year 4 | K19: Year 5 | L19: Year 6 | M19: Year 7 | N19: Year 8 | O19: Year 9 | P19: Year 10
E20: Total Revenue | G20: ='Annual Projections'!C2 -> 2470017000 | H20: ='Annual Projections'!D2 -> 2470017000 | I20: ='Annual Projections'!E2 -> 2544117510 | J20: ='Annual Projections'!F2 -> 2544117510 | K20: ='Annual Projections'!G2 -> 2.620441e+09 | L20: ='Annual Projections'!H2 -> 2.620441e+09 | M20: ='Annual Projections'!I2 -> 2.6990543e+09 | N20: ='Annual Projections'!J2 -> 2.6990543e+09 | ... P20: ='Annual Projections'!L2 -> 2.7800259e+09
A21: Splits of Stays (Monthly) | C21: =Assumptions!C22 -> 0.8 | E21: Cove Platform Fee | G21: ='Annual Projections'!C3 -> 0 | H21: ='Annual Projections'!D3 -> 0 | I21: ='Annual Projections'!E3 -> 0 | J21: ='Annual Projections'!F3 -> 0 | K21: ='Annual Projections'!G3 -> 0 | L21: ='Annual Projections'!H3 -> 0 | M21: ='Annual Projections'!I3 -> 0 | N21: ='Annual Projections'!J3 -> 0 | ... P21: ='Annual Projections'!L3 -> 0
A22: Splits of Stays (Daily) | C22: =Assumptions!C23 -> 0.2 | E22: OTA Cost | G22: ='Annual Projections'!C4 -> -145310880 | H22: ='Annual Projections'!D4 -> -145310880 | I22: ='Annual Projections'!E4 -> -1.4967021e+08 | J22: ='Annual Projections'!F4 -> -1.4967021e+08 | K22: ='Annual Projections'!G4 -> -1.5416031e+08 | L22: ='Annual Projections'!H4 -> -1.5416031e+08 | M22: ='Annual Projections'!I4 -> -1.5878512e+08 | N22: ='Annual Projections'!J4 -> -1.5878512e+08 | ... P22: ='Annual Projections'!L4 -> -1.6354868e+08
A23: Stabilized Occupancy (Monthly) | C23: =Assumptions!C24 -> 0.85 | E23: Net Revenue | G23: =SUM(G20:G22) -> 2324706120 | H23: =SUM(H20:H22) -> 2324706120 | I23: =SUM(I20:I22) -> 2.3944473e+09 | J23: =SUM(J20:J22) -> 2.3944473e+09 | K23: =SUM(K20:K22) -> 2.4662807e+09 | L23: =SUM(L20:L22) -> 2.4662807e+09 | M23: =SUM(M20:M22) -> 2.5402691e+09 | N23: =SUM(N20:N22) -> 2.5402691e+09 | ... P23: =SUM(P20:P22) -> 2.6164772e+09
A24: Stabilized Occupancy (Daily) | C24: =Assumptions!C25 -> 0.65 | E24: Operating Expenses (OPEX) | G24: ='Annual Projections'!C6 -> -835200000 | H24: ='Annual Projections'!D6 -> -884679000 | I24: ='Annual Projections'!E6 -> -896848830 | J24: ='Annual Projections'!F6 -> -9.0921282e+08 | K24: ='Annual Projections'!G6 -> -9.2177436e+08 | L24: ='Annual Projections'!H6 -> -9.345369e+08 | M24: ='Annual Projections'!I6 -> -9.4750396e+08 | N24: ='Annual Projections'!J6 -> -9.6067913e+08 | ... P24: ='Annual Projections'!L6 -> -9.8766845e+08
E25: Gross Operating Profit (GOP) | G25: =SUM(G23:G24) -> 1489506120 | H25: =SUM(H23:H24) -> 1440027120 | I25: =SUM(I23:I24) -> 1.4975985e+09 | J25: =SUM(J23:J24) -> 1.4852345e+09 | K25: =SUM(K23:K24) -> 1.5445064e+09 | L25: =SUM(L23:L24) -> 1.5317438e+09 | M25: =SUM(M23:M24) -> 1.5927652e+09 | N25: =SUM(N23:N24) -> 1.57959e+09 | ... P25: =SUM(P23:P24) -> 1.6288088e+09
E26: Cove Incentive Fee | G26: ='Annual Projections'!C8 -> 0 | H26: ='Annual Projections'!D8 -> 0 | I26: ='Annual Projections'!E8 -> 0 | J26: ='Annual Projections'!F8 -> 0 | K26: ='Annual Projections'!G8 -> 0 | L26: ='Annual Projections'!H8 -> 0 | M26: ='Annual Projections'!I8 -> 0 | N26: ='Annual Projections'!J8 -> 0 | ... P26: ='Annual Projections'!L8 -> 0
A27: Monthly Stays via Cove | C27: =Assumptions!C28 -> 1 | E27: (principal + interest) on loan | G27: ='Annual Projections'!C9 -> -3.5767077e+08 | H27: ='Annual Projections'!D9 -> -3.5767077e+08 | I27: ='Annual Projections'!E9 -> -3.5767077e+08 | J27: ='Annual Projections'!F9 -> -3.5767077e+08 | K27: ='Annual Projections'!G9 -> -3.5767077e+08 | L27: ='Annual Projections'!H9 -> -3.5767077e+08 | M27: ='Annual Projections'!I9 -> -3.5767077e+08 | N27: ='Annual Projections'!J9 -> -3.5767077e+08 | ... P27: ='Annual Projections'!L9 -> -3.5767077e+08
A28: Daily stays via Cove | C28: =Assumptions!C29 -> 0.2 | E28: Equity cash flow after debt | G28: =SUM(G25:G27) -> 1.1318353e+09 | H28: =SUM(H25:H27) -> 1.0823563e+09 | I28: =SUM(I25:I27) -> 1.1399277e+09 | J28: =SUM(J25:J27) -> 1.1275637e+09 | K28: =SUM(K25:K27) -> 1.1868356e+09 | L28: =SUM(L25:L27) -> 1.174073e+09 | M28: =SUM(M25:M27) -> 1.2350944e+09 | N28: =SUM(N25:N27) -> 1.2219192e+09 | ... P28: =SUM(P25:P27) -> 1.271138e+09
A29: Daily Stays via OTA | C29: =Assumptions!C30 -> 0.8 | E29: Equity cash flow | F29: ='Annual Projections'!B11 -> -3600000000 | G29: ='Annual Projections'!C11 -> 1.1318353e+09 | H29: ='Annual Projections'!D11 -> 1.0823563e+09 | I29: ='Annual Projections'!E11 -> 1.1399277e+09 | J29: ='Annual Projections'!F11 -> 1.1275637e+09 | K29: ='Annual Projections'!G11 -> 1.1868356e+09 | L29: ='Annual Projections'!H11 -> 1.174073e+09 | M29: ='Annual Projections'!I11 -> 1.2350944e+09 | ... P29: ='Annual Projections'!L11 -> 1.271138e+09
E30: Cumulative Cash Flow | F30: ='Annual Projections'!B12 -> -3600000000 | G30: ='Annual Projections'!C12 -> -2.4681647e+09 | H30: ='Annual Projections'!D12 -> -1.3858083e+09 | I30: ='Annual Projections'!E12 -> -2.4588061e+08 | J30: ='Annual Projections'!F12 -> 8.8168311e+08 | K30: ='Annual Projections'!G12 -> 2.0685187e+09 | L30: ='Annual Projections'!H12 -> 3.2425917e+09 | M30: ='Annual Projections'!I12 -> 4.4776862e+09 | ... P30: ='Annual Projections'!L12 -> 8.2554838e+09
A32: OTA Cost % | C32: =Assumptions!C33 -> 0.2 | E32: Equity IRR (levered) | F32: =IRR(F29:P29) -> 0.29480111
A33: Cove Platform Fee % | C33: =Assumptions!C34 -> 0 | E33: 2nd Year Yield-On-Cost | F33: =(H25+H26)/Assumptions!$C$3 -> 0.24000452
A34: Cove Incentive Fee % | C34: =Assumptions!C35 -> 0 | E34: Payback Period (Years) | F34: {=(COUNTIF(F30:P30,"<0")-1) + (-INDEX(F30:P30, COUNTIF(F30:P30,"<0")) / INDEX(F29:P29, COUNTIF(F30:P30,"<0")+1))} -> 3.2180636
A36: Annual Salary Increment | C36: =Assumptions!C37 -> 0.01 | E36: Equity NPV | F36: =NPV(WACC!C13,G29:P29)+F29 -> 3.0984038e+09
A37: Biannual Rent Increment | C37: =Assumptions!C38 -> 0.03
A38: Annual OPEX Increment | C38: =Assumptions!C39 -> 0.02

Sheet WACC
B2: Risk free Rate (Rf) | C2: 0.068
B3: Market Return (Rm) | C3: 0.11
B4: Beta | C4: 1.15
B5: Cost of debt (Rd) | C5: ='Loan Repayment Structure'!C4 -> 0.08
B6: Tax Rate | C6: 0.11
B7: Equity Value | C7: =Assumptions!C3-'Loan Repayment Structure'!C3 -> 3600000000
B8: Debt Value | C8: ='Loan Repayment Structure'!C3 -> 2400000000
B12: WACC | C12: =((C7/(C7+C8))*(C2+C4*(C3-C2)))+((C8/(C7+C8))*C5*(1-C6)) -> 0.09826
B13: Cost of equity (Ke) | C13: =C2+C4*(C3-C2) -> 0.1163

Sheet Opex Schedule
A1: Yearly Expenses | B1: Year 1 | C1: Year 2 | D1: Year 3 | E1: Year 4 | F1: Year 5 | G1: Year 6 | H1: Year 7 | I1: Year 8 | J1: Year 9 | K1: Year 10
A2: Building Electricity | B2: =10000000*12 -> 120000000 | C2: =B2*(1+Assumptions!$C$39) -> 122400000 | D2: =C2*(1+Assumptions!$C$39) -> 124848000 | E2: =D2*(1+Assumptions!$C$39) -> 127344960 | F2: =E2*(1+Assumptions!$C$39) -> 1.2989186e+08 | G2: =F2*(1+Assumptions!$C$39) -> 1.324897e+08 | H2: =G2*(1+Assumptions!$C$39) -> 1.3513949e+08 | I2: =H2*(1+Assumptions!$C$39) -> 1.3784228e+08 | J2: =I2*(1+Assumptions!$C$39) -> 1.4059913e+08 | K2: =J2*(1+Assumptions!$C$39) -> 1.4341111e+08
A3: Subscriptions | B3: =3000000*12 -> 36000000 | C3: =B3*(1+Assumptions!$C$39) -> 36720000 | D3: =C3*(1+Assumptions!$C$39) -> 37454400 | E3: =D3*(1+Assumptions!$C$39) -> 38203488 | F3: =E3*(1+Assumptions!$C$39) -> 38967558 | G3: =F3*(1+Assumptions!$C$39) -> 39746909 | H3: =G3*(1+Assumptions!$C$39) -> 40541847 | I3: =H3*(1+Assumptions!$C$39) -> 41352684 | J3: =I3*(1+Assumptions!$C$39) -> 42179738 | K3: =J3*(1+Assumptions!$C$39) -> 43023332
A4: AC Servicing | B4: =1500000*12 -> 18000000 | C4: =B4*(1+Assumptions!$C$39) -> 18360000 | D4: =C4*(1+Assumptions!$C$39) -> 18727200 | E4: =D4*(1+Assumptions!$C$39) -> 19101744 | F4: =E4*(1+Assumptions!$C$39) -> 19483779 | G4: =F4*(1+Assumptions!$C$39) -> 19873454 | H4: =G4*(1+Assumptions!$C$39) -> 20270924 | I4: =H4*(1+Assumptions!$C$39) -> 20676342 | J4: =I4*(1+Assumptions!$C$39) -> 21089869 | K4: =J4*(1+Assumptions!$C$39) -> 21511666
A5: MEP Maintenance | B5: =3000000*12 -> 36000000 | C5: =B5*(1+Assumptions!$C$39) -> 36720000 | D5: =C5*(1+Assumptions!$C$39) -> 37454400 | E5: =D5*(1+Assumptions!$C$39) -> 38203488 | F5: =E5*(1+Assumptions!$C$39) -> 38967558 | G5: =F5*(1+Assumptions!$C$39) -> 39746909 | H5: =G5*(1+Assumptions!$C$39) -> 40541847 | I5: =H5*(1+Assumptions!$C$39) -> 41352684 | J5: =I5*(1+Assumptions!$C$39) -> 42179738 | K5: =J5*(1+Assumptions!$C$39) -> 43023332
A6: Neighborhood Fees | B6: =600000*12 -> 7200000 | C6: =B6*(1+Assumptions!$C$39) -> 7344000 | D6: =C6*(1+Assumptions!$C$39) -> 7490880 | E6: =D6*(1+Assumptions!$C$39) -> 7640697.6 | F6: =E6*(1+Assumptions!$C$39) -> 7793511.6 | G6: =F6*(1+Assumptions!$C$39) -> 7949381.8 | H6: =G6*(1+Assumptions!$C$39) -> 8108369.4 | I6: =H6*(1+Assumptions!$C$39) -> 8270536.8 | J6: =I6*(1+Assumptions!$C$39) -> 8435947.5 | K6: =J6*(1+Assumptions!$C$39) -> 8604666.5
A7: Handyman Service Costs | B7: =2000000*12 -> 24000000 | C7: =B7*(1+Assumptions!$C$39) -> 24480000 | D7: =C7*(1+Assumptions!$C$39) -> 24969600 | E7: =D7*(1+Assumptions!$C$39) -> 25468992 | F7: =E7*(1+Assumptions!$C$39) -> 25978372 | G7: =F7*(1+Assumptions!$C$39) -> 26497939 | H7: =G7*(1+Assumptions!$C$39) -> 27027898 | I7: =H7*(1+Assumptions!$C$39) -> 27568456 | J7: =I7*(1+Assumptions!$C$39) -> 28119825 | K7: =J7*(1+Assumptions!$C$39) -> 28682222
A8: Payroll | B8: =B24*12 -> 450000000 | C8: =(B24*13)*(1+Assumptions!$C$37) -> 492375000 | D8: =C8*(1+Assumptions!$C$37) -> 497298750 | E8: =D8*(1+Assumptions!$C$37) -> 5.0227174e+08 | F8: =E8*(1+Assumptions!$C$37) -> 5.0729445e+08 | G8: =F8*(1+Assumptions!$C$37) -> 5.123674e+08 | H8: =G8*(1+Assumptions!$C$37) -> 5.1749107e+08 | I8: =H8*(1+Assumptions!$C$37) -> 5.2266598e+08 | J8: =I8*(1+Assumptions!$C$37) -> 5.2789264e+08 | K8: =J8*(1+Assumptions!$C$37) -> 5.3317157e+08
A9: Fixed Costs - Subtotal | B9: =SUM(B2:B8) -> 691200000 | C9: =SUM(C2:C8) -> 738399000 | D9: =SUM(D2:D8) -> 748243230 | E9: =SUM(E2:E8) -> 7.5823511e+08 | F9: =SUM(F2:F8) -> 7.6837709e+08 | G9: =SUM(G2:G8) -> 7.7867169e+08 | H9: =SUM(H2:H8) -> 7.8912145e+08 | I9: =SUM(I2:I8) -> 7.9972897e+08 | ... K9: =SUM(K2:K8) -> 8.214279e+08
A10: Water Bill | B10: =2500000*12 -> 30000000 | C10: =B10*(1+Assumptions!$C$32) -> 30000000 | D10: =C10*(1+Assumptions!$C$32) -> 30000000 | E10: =D10*(1+Assumptions!$C$32) -> 30000000 | F10: =E10*(1+Assumptions!$C$32) -> 30000000 | G10: =F10*(1+Assumptions!$C$32) -> 30000000 | H10: =G10*(1+Assumptions!$C$32) -> 30000000 | I10: =H10*(1+Assumptions!$C$32) -> 30000000 | J10: =I10*(1+Assumptions!$C$32) -> 30000000 | K10: =J10*(1+Assumptions!$C$32) -> 30000000
A11: STS Amenities | B11: =Assumptions!C4*Assumptions!C23*30*50000 -> 12000000 | C11: =B11*(1+Assumptions!$C$39) -> 12240000 | D11: =C11*(1+Assumptions!$C$39) -> 12484800 | E11: =D11*(1+Assumptions!$C$39) -> 12734496 | F11: =E11*(1+Assumptions!$C$39) -> 12989186 | G11: =F11*(1+Assumptions!$C$39) -> 13248970 | H11: =G11*(1+Assumptions!$C$39) -> 13513949 | I11: =H11*(1+Assumptions!$C$39) -> 13784228 | J11: =I11*(1+Assumptions!$C$39) -> 14059913 | K11: =J11*(1+Assumptions!$C$39) -> 14341111
A12: Cleaning | B12: =1000000*12 -> 12000000 | C12: =B12*(1+Assumptions!$C$39) -> 12240000 | D12: =C12*(1+Assumptions!$C$39) -> 12484800 | E12: =D12*(1+Assumptions!$C$39) -> 12734496 | F12: =E12*(1+Assumptions!$C$39) -> 12989186 | G12: =F12*(1+Assumptions!$C$39) -> 13248970 | H12: =G12*(1+Assumptions!$C$39) -> 13513949 | I12: =H12*(1+Assumptions!$C$39) -> 13784228 | J12: =I12*(1+Assumptions!$C$39) -> 14059913 | K12: =J12*(1+Assumptions!$C$39) -> 14341111
A13: Website Management | B13: =(7500000*12) -> 90000000 | C13: =B13*(1+Assumptions!$C$39) -> 91800000 | D13: =C13*(1+Assumptions!$C$39) -> 93636000 | E13: =D13*(1+Assumptions!$C$39) -> 95508720 | F13: =E13*(1+Assumptions!$C$39) -> 97418894 | G13: =F13*(1+Assumptions!$C$39) -> 99367272 | H13: =G13*(1+Assumptions!$C$39) -> 1.0135462e+08 | I13: =H13*(1+Assumptions!$C$39) -> 1.0338171e+08 | J13: =I13*(1+Assumptions!$C$39) -> 1.0544934e+08 | K13: =J13*(1+Assumptions!$C$39) -> 1.0755833e+08
A14: Variable Costs - Subtotal | B14: =SUM(B10:B13) -> 144000000 | C14: =SUM(C10:C13) -> 146280000 | D14: =SUM(D10:D13) -> 148605600 | E14: =SUM(E10:E13) -> 150977712 | F14: =SUM(F10:F13) -> 1.5339727e+08 | G14: =SUM(G10:G13) -> 1.5586521e+08 | H14: =SUM(H10:H13) -> 1.5838252e+08 | I14: =SUM(I10:I13) -> 1.6095017e+08 | ... K14: =SUM(K10:K13) -> 1.6624055e+08
A15: Total Operating Expenses | B15: =B9+B14 -> 835200000 | C15: =C9+C14 -> 884679000 | D15: =D9+D14 -> 896848830 | E15: =E9+E14 -> 9.0921282e+08 | F15: =F9+F14 -> 9.2177436e+08 | G15: =G9+G14 -> 9.345369e+08 | H15: =H9+H14 -> 9.4750396e+08 | I15: =I9+I14 -> 9.6067913e+08 | ... K15: =K9+K14 -> 9.8766845e+08
A17: Monthly Expenses | B17: Year 1 | C17: Year 2 | D17: Year 3 | E17: Year 4 | F17: Year 5 | G17: Year 6 | H17: Year 7 | I17: Year 8 | J17: Year 9 | K17: Year 10
A18: Building Electricity | B18: =B2/12 -> 10000000 | C18: =C2/12 -> 10200000 | D18: =D2/12 -> 10404000 | E18: =E2/12 -> 10612080 | F18: =F2/12 -> 10824322 | G18: =G2/12 -> 11040808 | H18: =H2/12 -> 11261624 | I18: =I2/12 -> 11486857 | ... K18: =K2/12 -> 11950926
A19: Subscriptions (Wifi, etc…) | B19: =B3/12 -> 3000000 | C19: =C3/12 -> 3060000 | D19: =D3/12 -> 3121200 | E19: =E3/12 -> 3183624 | F19: =F3/12 -> 3247296.5 | G19: =G3/12 -> 3312242.4 | H19: =H3/12 -> 3378487.3 | I19: =I3/12 -> 3446057 | ... K19: =K3/12 -> 3585277.7
A20: AC Servicing | B20: =B4/12 -> 1500000 | C20: =C4/12 -> 1530000 | D20: =D4/12 -> 1560600 | E20: =E4/12 -> 1591812 | F20: =F4/12 -> 1623648.2 | G20: =G4/12 -> 1656121.2 | H20: =H4/12 -> 1689243.6 | I20: =I4/12 -> 1723028.5 | ... K20: =K4/12 -> 1792638.9
A21: MEP Maintenance | B21: =B5/12 -> 3000000 | C21: =C5/12 -> 3060000 | D21: =D5/12 -> 3121200 | E21: =E5/12 -> 3183624 | F21: =F5/12 -> 3247296.5 | G21: =G5/12 -> 3312242.4 | H21: =H5/12 -> 3378487.3 | I21: =I5/12 -> 3446057 | ... K21: =K5/12 -> 3585277.7
A22: Neighborhood Fees | B22: =B6/12 -> 600000 | C22: =C6/12 -> 612000 | D22: =D6/12 -> 624240 | E22: =E6/12 -> 636724.8 | F22: =F6/12 -> 649459.3 | G22: =G6/12 -> 662448.48 | H22: =H6/12 -> 675697.45 | I22: =I6/12 -> 689211.4 | ... K22: =K6/12 -> 717055.54
A23: Handyman Service Costs | B23: =B7/12 -> 2000000 | C23: =C7/12 -> 2040000 | D23: =D7/12 -> 2080800 | E23: =E7/12 -> 2122416 | F23: =F7/12 -> 2164864.3 | G23: =G7/12 -> 2208161.6 | H23: =H7/12 -> 2252324.8 | I23: =I7/12 -> 2297371.3 | ... K23: =K7/12 -> 2390185.1
A24: Payroll | B24: ='Salary Details'!G8 -> 37500000 | C24: =C8/12 -> 41031250 | D24: =D8/12 -> 41441562 | E24: =E8/12 -> 41855978 | F24: =F8/12 -> 42274538 | G24: =G8/12 -> 42697283 | H24: =H8/12 -> 43124256 | I24: =I8/12 -> 43555499 | J24: =J8/12 -> 43991054 | K24: =K8/12 -> 44430964
A25: Fixed Costs - Subtotal | B25: =SUM(B18:B24) -> 57600000 | C25: =SUM(C18:C24) -> 61533250 | D25: =SUM(D18:D24) -> 62353602 | E25: =SUM(E18:E24) -> 63186259 | F25: =SUM(F18:F24) -> 64031424 | G25: =SUM(G18:G24) -> 64889307 | H25: =SUM(H18:H24) -> 65760121 | I25: =SUM(I18:I24) -> 66644081 | ... K25: =SUM(K18:K24) -> 68452325
A26: =A10 -> Water Bill | B26: =B10/12 -> 2500000 | C26: =C10/12 -> 2500000 | D26: =D10/12 -> 2500000 | E26: =E10/12 -> 2500000 | F26: =F10/12 -> 2500000 | G26: =G10/12 -> 2500000 | H26: =H10/12 -> 2500000 | I26: =I10/12 -> 2500000 | ... K26: =K10/12 -> 2500000
A27: =A11 -> STS Amenities | B27: =B11/12 -> 1000000 | C27: =C11/12 -> 1020000 | D27: =D11/12 -> 1040400 | E27: =E11/12 -> 1061208 | F27: =F11/12 -> 1082432.2 | G27: =G11/12 -> 1104080.8 | H27: =H11/12 -> 1126162.4 | I27: =I11/12 -> 1148685.7 | ... K27: =K11/12 -> 1195092.6
A28: =A12 -> Cleaning | B28: =B12/12 -> 1000000 | C28: =C12/12 -> 1020000 | D28: =D12/12 -> 1040400 | E28: =E12/12 -> 1061208 | F28: =F12/12 -> 1082432.2 | G28: =G12/12 -> 1104080.8 | H28: =H12/12 -> 1126162.4 | I28: =I12/12 -> 1148685.7 | ... K28: =K12/12 -> 1195092.6
A29: =A13 -> Website Management | B29: =B13/12 -> 7500000 | C29: =C13/12 -> 7650000 | D29: =D13/12 -> 7803000 | E29: =E13/12 -> 7959060 | F29: =F13/12 -> 8118241.2 | G29: =G13/12 -> 8280606 | H29: =H13/12 -> 8446218.1 | I29: =I13/12 -> 8615142.5 | ... K29: =K13/12 -> 8963194.3
A30: =A14 -> Variable Costs - Subtotal | B30: =SUM(B26:B29) -> 12000000 | C30: =SUM(C26:C29) -> 12190000 | D30: =SUM(D26:D29) -> 12383800 | E30: =SUM(E26:E29) -> 12581476 | F30: =SUM(F26:F29) -> 12783106 | G30: =SUM(G26:G29) -> 12988768 | H30: =SUM(H26:H29) -> 13198543 | I30: =SUM(I26:I29) -> 13412514 | ... K30: =SUM(K26:K29) -> 13853379
A31: Total Operating Expenses | B31: =B25+B30 -> 69600000 | C31: =C25+C30 -> 73723250 | D31: =D25+D30 -> 74737402 | E31: =E25+E30 -> 75767735 | F31: =F25+F30 -> 76814530 | G31: =G25+G30 -> 77878075 | H31: =H25+H30 -> 78958664 | I31: =I25+I30 -> 80056594 | ... K31: =K25+K30 -> 82305704

Sheet Assumptions
A3: Initial Investment | C3: 6000000000
A4: Total Rooms | C4: =C6+C10+C14+C18 -> 40
A6: Standard Rooms (16.5 sqm - 31 units) | C6: 31
A7: Superior + Montly rate | C7: 4600000
A8: Superior + Daily rate | C8: =C7/30*3 -> 460000
A10: Deluxe Rooms (20.4 sqm - 3 units) | C10: 3
A11: Deluxe Monthly Rate | C11: 5000000
A12: Deluxe Daily Rate | C12: =C11/30*3 -> 500000
A14: Premium 1 Rooms (26.4 sqm - 2 units) | C14: 2
A15: Premium 1 Montly rate | C15: 5900000
A16: Premium 1 Daily rate | C16: =(C15/30)*3 -> 590000
A18: Premium 2 Rooms (22.4 sqm - 4 units) | C18: 4
A19: Premium 2 Monthly rate | C19: 5500000
A20: Premium 2 Daily rate | C20: =(C19/30)*3 -> 550000
A22: Splits of Stays (Monthly) | C22: 0.8
A23: Splits of Stays (Daily) | C23: 0.2
A24: Stabilized Occupancy (Monthly) | C24: 0.85
A25: Stabilized Occupancy (Daily) | C25: 0.65
A28: Monthly Stays via Cove | C28: 1
A29: Daily stays via Cove | C29: 0.2
A30: Daily Stays via OTA | C30: 0.8
A33: OTA Cost % | C33: 0.2 | D33: We are assuming 50% of sales will come from online booking platforms such as agoda, traveloka, etc.
A34: Cove Platform Fee % | C34: 0
A35: Cove Incentive Fee % | C35: 0
A37: Annual Salary Increment | C37: 0.01
A38: Biannual Rent Increment | C38: 0.03
A39: Annual OPEX Increment | C39: 0.02

Sheet Annual Projections
A1: Line Item | B1: Year 0 | C1: Year 1 | D1: Year 2 | E1: Year 3 | F1: Year 4 | G1: Year 5 | H1: Year 6 | I1: Year 7 | J1: Year 8 | K1: Year 9 | L1: Year 10
A2: Total Revenue | C2: =((Assumptions!$C$6*Assumptions!$C$7*12*Assumptions!$C$22*Assumptions!$C$24)+(Assumptions!$C$10*Assumptions!$C$11*12*Assumptions!$C$22*Assumptions!$C$24)+(Assumptions!$C$14*Assumptions!$C$15*12*Assumptions!$C$22*Assumptions!$C$24)+(Assumptions!$C$18*Assumptions!$C$19*12*Assumptions!$C$22*Assumptions!$C$24))+((Assumptions!$C$6*Assumptions!$C$8*365*Assumptions!$C$23*Assumptions!$C$25)+(Assumptions!$C$10*Assumptions!$C$12*365*Assumptions!$C$23*Assumptions!$C$25)+(Assumptions!$C$14*Assumptions!$C$16*365*Assumptions!$C$23*Assumptions!$C$25)+(Assumptions!$C$18*Assumptions!$C$20*365*Assumptions!$C$23*Assumptions!$C$25)) -> 2470017000 | D2: =C2 -> 2470017000 | E2: =D2*(1+Assumptions!$C$38) -> 2544117510 | F2: =E2 -> 2544117510 | G2: =F2*(1+Assumptions!$C$38) -> 2.620441e+09 | H2: =G2 -> 2.620441e+09 | I2: =H2*(1+Assumptions!$C$38) -> 2.6990543e+09 | J2: =I2 -> 2.6990543e+09 | K2: =J2*(1+Assumptions!$C$38) -> 2.7800259e+09 | L2: =K2 -> 2.7800259e+09
A3: Cove Platform Fee | C3: =-C2*Assumptions!$C$34 -> 0 | D3: =-D2*Assumptions!$C$34 -> 0 | E3: =-E2*Assumptions!$C$34 -> 0 | F3: =-F2*Assumptions!$C$34 -> 0 | G3: =-G2*Assumptions!$C$34 -> 0 | H3: =-H2*Assumptions!$C$34 -> 0 | I3: =-I2*Assumptions!$C$34 -> 0 | J3: =-J2*Assumptions!$C$34 -> 0 | ... L3: =-L2*Assumptions!$C$34 -> 0
A4: OTA Cost | C4: =-((Assumptions!$C$6*Assumptions!$C$8*365*Assumptions!$C$23*Assumptions!$C$25*Assumptions!$C$30)+(Assumptions!$C$10*Assumptions!$C$12*365*Assumptions!$C$23*Assumptions!$C$25*Assumptions!$C$30)+(Assumptions!$C$14*Assumptions!$C$16*365*Assumptions!$C$23*Assumptions!$C$25*Assumptions!$C$30)+(Assumptions!$C$18*Assumptions!$C$20*365*Assumptions!$C$23*Assumptions!$C$25*Assumptions!$C$30))*Assumptions!$C$33 -> -145310880 | D4: =C4 -> -145310880 | E4: =D4*(1+Assumptions!$C$38) -> -1.4967021e+08 | F4: =E4 -> -1.4967021e+08 | G4: =F4*(1+Assumptions!C38) -> -1.5416031e+08 | H4: =G4 -> -1.5416031e+08 | I4: =H4*(1+Assumptions!C38) -> -1.5878512e+08 | J4: =I4 -> -1.5878512e+08 | K4: =J4*(1+Assumptions!$C$38) -> -1.6354868e+08 | L4: =K4 -> -1.6354868e+08
A5: Net Revenue | C5: =SUM(C2:C4) -> 2324706120 | D5: =SUM(D2:D4) -> 2324706120 | E5: =SUM(E2:E4) -> 2.3944473e+09 | F5: =SUM(F2:F4) -> 2.3944473e+09 | G5: =SUM(G2:G4) -> 2.4662807e+09 | H5: =SUM(H2:H4) -> 2.4662807e+09 | I5: =SUM(I2:I4) -> 2.5402691e+09 | J5: =SUM(J2:J4) -> 2.5402691e+09 | ... L5: =SUM(L2:L4) -> 2.6164772e+09
A6: Operating Expenses (OPEX) | C6: =-'Opex Schedule'!B15 -> -835200000 | D6: =-'Opex Schedule'!C15 -> -884679000 | E6: =-'Opex Schedule'!D15 -> -896848830 | F6: =-'Opex Schedule'!E15 -> -9.0921282e+08 | G6: =-'Opex Schedule'!F15 -> -9.2177436e+08 | H6: =-'Opex Schedule'!G15 -> -9.345369e+08 | I6: =-'Opex Schedule'!H15 -> -9.4750396e+08 | J6: =-'Opex Schedule'!I15 -> -9.6067913e+08 | ... L6: =-'Opex Schedule'!K15 -> -9.8766845e+08
A7: Gross Operating Profit (GOP) | C7: =SUM(C5:C6) -> 1489506120 | D7: =SUM(D5:D6) -> 1440027120 | E7: =SUM(E5:E6) -> 1.4975985e+09 | F7: =SUM(F5:F6) -> 1.4852345e+09 | G7: =SUM(G5:G6) -> 1.5445064e+09 | H7: =SUM(H5:H6) -> 1.5317438e+09 | I7: =SUM(I5:I6) -> 1.5927652e+09 | J7: =SUM(J5:J6) -> 1.57959e+09 | ... L7: =SUM(L5:L6) -> 1.6288088e+09
A8: Cove Incentive Fee | C8: =-C7*Assumptions!$C$35 -> 0 | D8: =-D7*Assumptions!$C$35 -> 0 | E8: =-E7*Assumptions!$C$35 -> 0 | F8: =-F7*Assumptions!$C$35 -> 0 | G8: =-G7*Assumptions!$C$35 -> 0 | H8: =-H7*Assumptions!$C$35 -> 0 | I8: =-I7*Assumptions!$C$35 -> 0 | J8: =-J7*Assumptions!$C$35 -> 0 | ... L8: =-L7*Assumptions!$C$35 -> 0
A9: Loan repayment - (Interest + principle) | C9: =-'Loan Repayment Structure'!C13 -> -3.5767077e+08 | D9: =-'Loan Repayment Structure'!D13 -> -3.5767077e+08 | E9: =-'Loan Repayment Structure'!E13 -> -3.5767077e+08 | F9: =-'Loan Repayment Structure'!F13 -> -3.5767077e+08 | G9: =-'Loan Repayment Structure'!G13 -> -3.5767077e+08 | H9: =-'Loan Repayment Structure'!H13 -> -3.5767077e+08 | I9: =-'Loan Repayment Structure'!I13 -> -3.5767077e+08 | J9: =-'Loan Repayment Structure'!J13 -> -3.5767077e+08 | ... L9: =-'Loan Repayment Structure'!L13 -> -3.5767077e+08
A10: Owner Share (NOI) | C10: =SUM(C7:C9) -> 1.1318353e+09 | D10: =SUM(D7:D9) -> 1.0823563e+09 | E10: =SUM(E7:E9) -> 1.1399277e+09 | F10: =SUM(F7:F9) -> 1.1275637e+09 | G10: =SUM(G7:G9) -> 1.1868356e+09 | H10: =SUM(H7:H9) -> 1.174073e+09 | I10: =SUM(I7:I9) -> 1.2350944e+09 | J10: =SUM(J7:J9) -> 1.2219192e+09 | ... L10: =SUM(L7:L9) -> 1.271138e+09
A11: Project Cash Flow | B11: =-(Assumptions!C3-'Loan Repayment Structure'!C3) -> -3600000000 | C11: =C10 -> 1.1318353e+09 | D11: =D10 -> 1.0823563e+09 | E11: =E10 -> 1.1399277e+09 | F11: =F10 -> 1.1275637e+09 | G11: =G10 -> 1.1868356e+09 | H11: =H10 -> 1.174073e+09 | I11: =I10 -> 1.2350944e+09 | J11: =J10 -> 1.2219192e+09 | ... L11: =L10 -> 1.271138e+09
A12: Cumulative Cash Flow | B12: =B11 -> -3600000000 | C12: =B12+C11 -> -2.4681647e+09 | D12: =C12+D11 -> -1.3858083e+09 | E12: =D12+E11 -> -2.4588061e+08 | F12: =E12+F11 -> 8.8168311e+08 | G12: =F12+G11 -> 2.0685187e+09 | H12: =G12+H11 -> 3.2425917e+09 | I12: =H12+I11 -> 4.4776862e+09 | J12: =I12+J11 -> 5.6996054e+09 | ... L12: =K12+L11 -> 8.2554838e+09
A14: Project Unlevered IRR | B14: =IRR(B11:L11) -> 0.29480111
A15: 2nd Year Yield-On-Cost | B15: =SUM(D7:D8)/Assumptions!C3 -> 0.24000452
A16: Payback Period (Years) | B16: {=(COUNTIF(B12:L12,"<0")-1) + (-INDEX(B12:L12, COUNTIF(B12:L12,"<0")) / INDEX(B11:L11, COUNTIF(B12:L12,"<0")+1))} -> 3.2180636
A22: Total loan amt | B22: =Assumptions!C3*40% -> 2400000000
B23: How is the loan repayment structure?
B24: is it amortized (principle + interest) or we need to pay a lump sum at the end
B25: Answer: 8% through 10 years, while repaying principle as well

Sheet Loan Repayment Structure
B2: Loan Details | E2: Outflow simulation per year
B3: Principal | C3: =40%*Assumptions!C3 -> 2400000000 | E3: Particulars | F3: Dr | G3: Cr
B4: Interest rate | C4: 0.08 | E4: Interest Expense | F4: =8%*C3 -> 192000000
B5: Tenure | C5: 10 | E5: Loan payable | F5: =C9-F4 -> 1.6567077e+08
B6: Repayment type | C6: Equal annual installments (principle + interest) | E6: Cash | G6: =C9 -> 3.5767077e+08
B8: IPMT | C8: =IPMT(C4,1,C5,-C3,,0) -> 192000000
B9: PMT | C9: =PMT(C4,C5,-C3,,0) -> 3.5767077e+08
B11: Year | C11: 1 | D11: 2 | E11: 3 | F11: 4 | G11: 5 | H11: 6 | I11: 7 | J11: 8 | K11: 9 | L11: 10
B12: Opening balance | C12: =C3 -> 2400000000 | D12: =C16 -> 2.2343292e+09 | E12: =D16 -> 2.0554048e+09 | F12: =E16 -> 1.8621664e+09 | G12: =F16 -> 1.6534689e+09 | H12: =G16 -> 1.4280757e+09 | I12: =H16 -> 1.184651e+09 | J12: =I16 -> 9.2175227e+08 | K12: =J16 -> 6.3782168e+08 | L12: =K16 -> 3.3117664e+08
B13: Annual Installment | C13: =$C$9 -> 3.5767077e+08 | D13: =$C$9 -> 3.5767077e+08 | E13: =$C$9 -> 3.5767077e+08 | F13: =$C$9 -> 3.5767077e+08 | G13: =$C$9 -> 3.5767077e+08 | H13: =$C$9 -> 3.5767077e+08 | I13: =$C$9 -> 3.5767077e+08 | J13: =$C$9 -> 3.5767077e+08 | ... L13: =$C$9 -> 3.5767077e+08
B14: Interest (8%) | C14: =C12*8% -> 192000000 | D14: =D12*8% -> 1.7874634e+08 | E14: =E12*8% -> 1.6443238e+08 | F14: =F12*8% -> 1.4897331e+08 | G14: =G12*8% -> 1.3227752e+08 | H14: =H12*8% -> 1.1424605e+08 | I14: =I12*8% -> 94772077 | J14: =J12*8% -> 73740182 | ... L14: =L12*8% -> 26494131
B15: Principle Repaid | C15: =C13-C14 -> 1.6567077e+08 | D15: =D13-D14 -> 1.7892443e+08 | E15: =E13-E14 -> 1.9323839e+08 | F15: =F13-F14 -> 2.0869746e+08 | G15: =G13-G14 -> 2.2539326e+08 | H15: =H13-H14 -> 2.4342472e+08 | I15: =I13-I14 -> 2.628987e+08 | J15: =J13-J14 -> 2.8393059e+08 | ... L15: =L13-L14 -> 3.3117664e+08
B16: Closing Balance | C16: =C12-C15 -> 2.2343292e+09 | D16: =D12-D15 -> 2.0554048e+09 | E16: =E12-E15 -> 1.8621664e+09 | F16: =F12-F15 -> 1.6534689e+09 | G16: =G12-G15 -> 1.4280757e+09 | H16: =H12-H15 -> 1.184651e+09 | I16: =I12-I15 -> 9.2175227e+08 | J16: =J12-J15 -> 6.3782168e+08 | ... L16: =L12-L15 -> 1.1920929e-06

Sheet Salary Details
D2: Salary Details
D3: Particulars | E3: Amt | F3: Salary | G3: Total
D4: Manager | E4: 1 | F4: 6000000 | G4: =E4*F4 -> 6000000
D5: Receptionist | E5: 1 | F5: 3500000 | G5: =E5*F5 -> 3500000
D6: Security | E6: 4 | F6: =2500000 -> 2500000 | G6: =E6*F6 -> 10000000
D7: Housekeeping | E7: 6 | F7: =3000000 -> 3000000 | G7: =E7*F7 -> 18000000
G8: =SUM(G4:G7) -> 37500000

Sheet Financial Model (2)
A1: Project Assumptions | C1: Values
A2: Investment
A3: Initial Investment (Landlord) | C3: 6500000000
A5: Operations
A6: Number of Rooms | C6: 44
A7: Average Monthly Rent per Room | C7: 4600000
A9: Growth & Inflation
A10: Annual Rent Growth | C10: 0.05
A11: Annual OPEX Growth
A13: Occupancy Ramp-Up
A14: Year 1 Occupancy | C14: 0.85
A15: Stabilized Occupancy (Y2+) | C15: 0.92
A17: Fees & Costs (% of Total Revenue)
A18: Cove Platform Fee | C18: 0.025
A19: OTA Cost | C19: 0.093
A20: OPEX (% of Net Revenue) | C20: 0.296
A21: Cove Incentive Fee (% of GOP) | C21: 0.18
A24: Line Item | B24: Year 0 | C24: Year 1 | D24: Year 2 | E24: Year 3 | F24: Year 4 | G24: Year 5 | H24: Year 6 | I24: Year 7 | J24: Year 8 | K24: Year 9 | L24: Year 10
A25: Revenue
A26: Gross Potential Rent | C26: =$C$6*$C$7*12 -> 2428800000 | D26: =C26*(1+$C$10) -> 2550240000 | E26: =D26*(1+$C$10) -> 2677752000 | F26: =E26*(1+$C$10) -> 2811639600 | G26: =F26*(1+$C$10) -> 2952221580 | H26: =G26*(1+$C$10) -> 3099832659 | I26: =H26*(1+$C$10) -> 3.2548243e+09 | J26: =I26*(1+$C$10) -> 3.4175655e+09 | K26: =J26*(1+$C$10) -> 3.5884438e+09 | L26: =K26*(1+$C$10) -> 3.767866e+09
A27: Vacancy Loss | C27: =C26*(1-$C$14) -> 3.6432e+08 | D27: =D26*(1-$C$15) -> 2.040192e+08 | E27: =E26*(1-$C$15) -> 2.1422016e+08 | F27: =F26*(1-$C$15) -> 2.2493117e+08 | G27: =G26*(1-$C$15) -> 2.3617773e+08 | H27: =H26*(1-$C$15) -> 2.4798661e+08 | I27: =I26*(1-$C$15) -> 2.6038594e+08 | J27: =J26*(1-$C$15) -> 2.7340524e+08 | K27: =K26*(1-$C$15) -> 2.870755e+08 | L27: =L26*(1-$C$15) -> 3.0142928e+08
A28: Total Revenue | C28: =C26-C27 -> 2064480000 | D28: =D26-D27 -> 2346220800 | E28: =E26-E27 -> 2463531840 | F28: =F26-F27 -> 2586708432 | G28: =G26-G27 -> 2.7160439e+09 | H28: =H26-H27 -> 2.851846e+09 | I28: =I26-I27 -> 2.9944383e+09 | J28: =J26-J27 -> 3.1441603e+09 | ... L28: =L26-L27 -> 3.4664367e+09
A29: Deductions
A30: Cove Platform Fee | C30: =-C28*$C$18 -> -51612000 | D30: =-D28*$C$18 -> -58655520 | E30: =-E28*$C$18 -> -61588296 | F30: =-F28*$C$18 -> -64667711 | G30: =-G28*$C$18 -> -67901096 | H30: =-H28*$C$18 -> -71296151 | I30: =-I28*$C$18 -> -74860959 | J30: =-J28*$C$18 -> -78604007 | ... L30: =-L28*$C$18 -> -86660917
A31: OTA Cost | C31: =-C28*$C$19 -> -191996640 | D31: =-D28*$C$19 -> -2.1819853e+08 | E31: =-E28*$C$19 -> -2.2910846e+08 | F31: =-F28*$C$19 -> -2.4056388e+08 | G31: =-G28*$C$19 -> -2.5259208e+08 | H31: =-H28*$C$19 -> -2.6522168e+08 | I31: =-I28*$C$19 -> -2.7848277e+08 | J31: =-J28*$C$19 -> -2.924069e+08 | ... L31: =-L28*$C$19 -> -3.2237861e+08
A32: Net Revenue | C32: =SUM(C28:C31) -> 1820871360 | D32: =SUM(D28:D31) -> 2.0693667e+09 | E32: =SUM(E28:E31) -> 2.1728351e+09 | F32: =SUM(F28:F31) -> 2.2814768e+09 | G32: =SUM(G28:G31) -> 2.3955507e+09 | H32: =SUM(H28:H31) -> 2.5153282e+09 | I32: =SUM(I28:I31) -> 2.6410946e+09 | J32: =SUM(J28:J31) -> 2.7731494e+09 | ... L32: =SUM(L28:L31) -> 3.0573972e+09
A33: Operating Expenses (OPEX) | C33: =-C28*$C$20 -> -611086080 | D33: =C33*(1+$C$11) -> -611086080 | E33: =D33*(1+$C$11) -> -611086080 | F33: =E33*(1+$C$11) -> -611086080 | G33: =F33*(1+$C$11) -> -611086080 | H33: =G33*(1+$C$11) -> -611086080 | I33: =H33*(1+$C$11) -> -611086080 | J33: =I33*(1+$C$11) -> -611086080 | K33: =J33*(1+$C$11) -> -611086080 | L33: =K33*(1+$C$11) -> -611086080
A34: Gross Operating Profit (GOP) | C34: =SUM(C32:C33) -> 1209785280 | D34: =SUM(D32:D33) -> 1.4582807e+09 | E34: =SUM(E32:E33) -> 1.561749e+09 | F34: =SUM(F32:F33) -> 1.6703908e+09 | G34: =SUM(G32:G33) -> 1.7844646e+09 | H34: =SUM(H32:H33) -> 1.9042421e+09 | I34: =SUM(I32:I33) -> 2.0300085e+09 | J34: =SUM(J32:J33) -> 2.1620633e+09 | ... L34: =SUM(L32:L33) -> 2.4463111e+09
A35: Cove Incentive Fee | C35: =-C34*$C$21 -> -2.1776135e+08 | D35: =-D34*$C$21 -> -2.6249052e+08 | E35: =-E34*$C$21 -> -2.8111482e+08 | F35: =-F34*$C$21 -> -3.0067034e+08 | G35: =-G34*$C$21 -> -3.2120363e+08 | H35: =-H34*$C$21 -> -3.4276358e+08 | I35: =-I34*$C$21 -> -3.6540154e+08 | J35: =-J34*$C$21 -> -3.8917139e+08 | ... L35: =-L34*$C$21 -> -4.40336e+08
A36: Owner Share (NOI) | C36: =SUM(C34:C35) -> 9.9202393e+08 | D36: =SUM(D34:D35) -> 1.1957901e+09 | E36: =SUM(E34:E35) -> 1.2806342e+09 | F36: =SUM(F34:F35) -> 1.3697204e+09 | G36: =SUM(G34:G35) -> 1.463261e+09 | H36: =SUM(H34:H35) -> 1.5614785e+09 | I36: =SUM(I34:I35) -> 1.664607e+09 | J36: =SUM(J34:J35) -> 1.7728919e+09 | ... L36: =SUM(L34:L35) -> 2.0059751e+09
A37: Project Cash Flow | B37: =-$C$3 -> -6500000000 | C37: =C36 -> 9.9202393e+08 | D37: =D36 -> 1.1957901e+09 | E37: =E36 -> 1.2806342e+09 | F37: =F36 -> 1.3697204e+09 | G37: =G36 -> 1.463261e+09 | H37: =H36 -> 1.5614785e+09 | I37: =I36 -> 1.664607e+09 | J37: =J36 -> 1.7728919e+09 | ... L37: =L36 -> 2.0059751e+09
A38: Cumulative Cash Flow | B38: =B37 -> -6500000000 | C38: =B38+C37 -> -5.5079761e+09 | D38: =C38+D37 -> -4.3121859e+09 | E38: =D38+E37 -> -3.0315517e+09 | F38: =E38+F37 -> -1.6618313e+09 | G38: =F38+G37 -> -1.9857035e+08 | H38: =G38+H37 -> 1.3629082e+09 | I38: =H38+I37 -> 3.0275152e+09 | J38: =I38+J37 -> 4.8004071e+09 | ... L38: =K38+L37 -> 8.6929732e+09
A40: Cash Flow for IRR | B40: =-$C$3 -> -6500000000 | J40: Occupancy Break-Even
A41: Year 1 | B41: =C37 -> 9.9202393e+08 | J41: Break even no of rooms | K41: =-((D30+D31+D33+D35)/12)/C7 -> 20.841135
A42: Year 2 | B42: =D$37 -> 1.1957901e+09 | J42: Break even occupancy % | K42: =K41/C6 -> 0.47366216
A43: Year 3 | B43: =E$37 -> 1.2806342e+09 | J43: We need to rent 18 rooms in order to cover all the monthly costs
A44: Year 4 | B44: =F$37 -> 1.3697204e+09
A45: Year 5 | B45: =G$37 -> 1.463261e+09
A46: Year 6 | B46: =H$37 -> 1.5614785e+09
A47: Year 7 | B47: =I$37 -> 1.664607e+09
...

Sheet Sheet10

Sheet Financial Model (87%)
A1: Project Assumptions | C1: Values
A2: Investment
A3: Initial Investment (Landlord) | C3: 7000000000
A5: Operations
A6: Number of Rooms | C6: 38
A7: Average Monthly Rent per Room | C7: 4600000
A9: Growth & Inflation
A10: Annual Rent Growth | C10: 0.03
A11: Annual OPEX Growth | C11: 0.025
A13: Occupancy Ramp-Up
A14: Year 1 Occupancy | C14: 0.85
A15: Stabilized Occupancy (Y2+) | C15: 0.87
A17: Fees & Costs (% of Total Revenue)
A18: Cove Platform Fee | C18: 0.025
A19: OTA Cost | C19: 0.093
A20: OPEX (% of Net Revenue) | C20: 0.296
A21: Cove Incentive Fee (% of GOP) | C21: 0.18
A24: Line Item | B24: Year 0 | C24: Year 1 | D24: Year 2 | E24: Year 3 | F24: Year 4 | G24: Year 5 | H24: Year 6 | I24: Year 7 | J24: Year 8 | K24: Year 9 | L24: Year 10
A25: Revenue
A26: Gross Potential Rent | C26: =$C$6*$C$7*12 -> 2097600000 | D26: =C26*(1+$C$10) -> 2160528000 | E26: =D26*(1+$C$10) -> 2225343840 | F26: =E26*(1+$C$10) -> 2.2921042e+09 | G26: =F26*(1+$C$10) -> 2.3608673e+09 | H26: =G26*(1+$C$10) -> 2.4316933e+09 | I26: =H26*(1+$C$10) -> 2.5046441e+09 | J26: =I26*(1+$C$10) -> 2.5797834e+09 | K26: =J26*(1+$C$10) -> 2.6571769e+09 | L26: =K26*(1+$C$10) -> 2.7368922e+09
A27: Vacancy Loss | C27: =C26*(1-$C$14) -> 3.1464e+08 | D27: =D26*(1-$C$15) -> 280868640 | E27: =E26*(1-$C$15) -> 2.892947e+08 | F27: =F26*(1-$C$15) -> 2.9797354e+08 | G27: =G26*(1-$C$15) -> 3.0691275e+08 | H27: =H26*(1-$C$15) -> 3.1612013e+08 | I27: =I26*(1-$C$15) -> 3.2560373e+08 | J27: =J26*(1-$C$15) -> 3.3537184e+08 | K27: =K26*(1-$C$15) -> 3.45433e+08 | L27: =L26*(1-$C$15) -> 3.5579599e+08
A28: Total Revenue | C28: =C26-C27 -> 1782960000 | D28: =D26-D27 -> 1879659360 | E28: =E26-E27 -> 1.9360491e+09 | F28: =F26-F27 -> 1.9941306e+09 | G28: =G26-G27 -> 2.0539545e+09 | H28: =H26-H27 -> 2.1155732e+09 | I28: =I26-I27 -> 2.1790404e+09 | J28: =J26-J27 -> 2.2444116e+09 | ... L28: =L26-L27 -> 2.3810962e+09
A29: Deductions
A30: Cove Platform Fee | C30: =-C28*$C$18 -> -44574000 | D30: =-D28*$C$18 -> -46991484 | E30: =-E28*$C$18 -> -48401229 | F30: =-F28*$C$18 -> -49853265 | G30: =-G28*$C$18 -> -51348863 | H30: =-H28*$C$18 -> -52889329 | I30: =-I28*$C$18 -> -54476009 | J30: =-J28*$C$18 -> -56110289 | ... L30: =-L28*$C$18 -> -59527406
A31: OTA Cost | C31: =-C28*$C$19 -> -165815280 | D31: =-D28*$C$19 -> -1.7480832e+08 | E31: =-E28*$C$19 -> -1.8005257e+08 | F31: =-F28*$C$19 -> -1.8545415e+08 | G31: =-G28*$C$19 -> -1.9101777e+08 | H31: =-H28*$C$19 -> -1.967483e+08 | I31: =-I28*$C$19 -> -2.0265075e+08 | J31: =-J28*$C$19 -> -2.0873028e+08 | ... L31: =-L28*$C$19 -> -2.2144195e+08
A32: Net Revenue | C32: =SUM(C28:C31) -> 1572570720 | D32: =SUM(D28:D31) -> 1.6578596e+09 | E32: =SUM(E28:E31) -> 1.7075953e+09 | F32: =SUM(F28:F31) -> 1.7588232e+09 | G32: =SUM(G28:G31) -> 1.8115879e+09 | H32: =SUM(H28:H31) -> 1.8659355e+09 | I32: =SUM(I28:I31) -> 1.9219136e+09 | J32: =SUM(J28:J31) -> 1.979571e+09 | ... L32: =SUM(L28:L31) -> 2.1001269e+09
A33: Operating Expenses (OPEX) | C33: =-C28*$C$20 -> -527756160 | D33: =C33*(1+$C$11) -> -540950064 | E33: =D33*(1+$C$11) -> -5.5447382e+08 | F33: =E33*(1+$C$11) -> -5.6833566e+08 | G33: =F33*(1+$C$11) -> -5.8254405e+08 | H33: =G33*(1+$C$11) -> -5.9710765e+08 | I33: =H33*(1+$C$11) -> -6.1203535e+08 | J33: =I33*(1+$C$11) -> -6.2733623e+08 | K33: =J33*(1+$C$11) -> -6.4301963e+08 | L33: =K33*(1+$C$11) -> -6.5909513e+08
A34: Gross Operating Profit (GOP) | C34: =SUM(C32:C33) -> 1044814560 | D34: =SUM(D32:D33) -> 1.1169095e+09 | E34: =SUM(E32:E33) -> 1.1531215e+09 | F34: =SUM(F32:F33) -> 1.1904875e+09 | G34: =SUM(G32:G33) -> 1.2290438e+09 | H34: =SUM(H32:H33) -> 1.2688279e+09 | I34: =SUM(I32:I33) -> 1.3098783e+09 | J34: =SUM(J32:J33) -> 1.3522348e+09 | ... L34: =SUM(L32:L33) -> 1.4410318e+09
A35: Cove Incentive Fee | C35: =-C34*$C$21 -> -1.8806662e+08 | D35: =-D34*$C$21 -> -2.0104371e+08 | E35: =-E34*$C$21 -> -2.0756187e+08 | F35: =-F34*$C$21 -> -2.1428776e+08 | G35: =-G34*$C$21 -> -2.2122789e+08 | H35: =-H34*$C$21 -> -2.2838902e+08 | I35: =-I34*$C$21 -> -2.3577809e+08 | J35: =-J34*$C$21 -> -2.4340226e+08 | ... L35: =-L34*$C$21 -> -2.5938572e+08
A36: Owner Share (NOI) | C36: =SUM(C34:C35) -> 8.5674794e+08 | D36: =SUM(D34:D35) -> 9.1586578e+08 | E36: =SUM(E34:E35) -> 9.4555965e+08 | F36: =SUM(F34:F35) -> 9.7619978e+08 | G36: =SUM(G34:G35) -> 1.007816e+09 | H36: =SUM(H34:H35) -> 1.0404389e+09 | I36: =SUM(I34:I35) -> 1.0741002e+09 | J36: =SUM(J34:J35) -> 1.1088325e+09 | ... L36: =SUM(L34:L35) -> 1.181646e+09
A37: Project Cash Flow | B37: =-$C$3 -> -7000000000 | C37: =C36 -> 8.5674794e+08 | D37: =D36 -> 9.1586578e+08 | E37: =E36 -> 9.4555965e+08 | F37: =F36 -> 9.7619978e+08 | G37: =G36 -> 1.007816e+09 | H37: =H36 -> 1.0404389e+09 | I37: =I36 -> 1.0741002e+09 | J37: =J36 -> 1.1088325e+09 | ... L37: =L36 -> 1.181646e+09
A38: Cumulative Cash Flow | B38: =B37 -> -7000000000 | C38: =B38+C37 -> -6.1432521e+09 | D38: =C38+D37 -> -5.2273863e+09 | E38: =D38+E37 -> -4.2818266e+09 | F38: =E38+F37 -> -3.3056268e+09 | G38: =F38+G37 -> -2.2978109e+09 | H38: =G38+H37 -> -1.257372e+09 | I38: =H38+I37 -> -1.8327186e+08 | J38: =I38+J37 -> 9.2556067e+08 | ... L38: =K38+L37 -> 3.2518763e+09
A40: Cash Flow for IRR | B40: =-$C$3 -> -7000000000 | J40: Occupancy Break-Even
A41: Year 1 | B41: =C37 -> 8.5674794e+08 | J41: Break even no of rooms | K41: =-((D30+D31+D33+D35)/12)/C7 -> 17.460029
A42: Year 2 | B42: =D$37 -> 9.1586578e+08 | J42: Break even occupancy % | K42: =K41/C6 -> 0.45947444
A43: Year 3 | B43: =E$37 -> 9.4555965e+08 | J43: We need to rent 18 rooms in order to cover all the monthly costs
A44: Year 4 | B44: =F$37 -> 9.7619978e+08
A45: Year 5 | B45: =G$37 -> 1.007816e+09
A46: Year 6 | B46: =H$37 -> 1.0404389e+09
A47: Year 7 | B47: =I$37 -> 1.0741002e+09
...

Sheet Financial Model (60%)
A1: Project Assumptions | C1: Values
A2: Investment
A3: Initial Investment (Landlord) | C3: 7000000000
A5: Operations
A6: Number of Rooms | C6: 38
A7: Average Monthly Rent per Room | C7: 4600000
A9: Growth & Inflation
A10: Annual Rent Growth | C10: 0.03
A11: Annual OPEX Growth | C11: 0.025
A13: Occupancy Ramp-Up
A14: Year 1 Occupancy | C14: 0.85
A15: Stabilized Occupancy (Y2+) | C15: 0.6
A17: Fees & Costs (% of Total Revenue)
A18: Cove Platform Fee | C18: 0.025
A19: OTA Cost | C19: 0.093
A20: OPEX (% of Net Revenue) | C20: 0.296
A21: Cove Incentive Fee (% of GOP) | C21: 0.18
A24: Line Item | B24: Year 0 | C24: Year 1 | D24: Year 2 | E24: Year 3 | F24: Year 4 | G24: Year 5 | H24: Year 6 | I24: Year 7 | J24: Year 8 | K24: Year 9 | L24: Year 10
A25: Revenue
A26: Gross Potential Rent | C26: =$C$6*$C$7*12 -> 2097600000 | D26: =C26*(1+$C$10) -> 2160528000 | E26: =D26*(1+$C$10) -> 2225343840 | F26: =E26*(1+$C$10) -> 2.2921042e+09 | G26: =F26*(1+$C$10) -> 2.3608673e+09 | H26: =G26*(1+$C$10) -> 2.4316933e+09 | I26: =H26*(1+$C$10) -> 2.5046441e+09 | J26: =I26*(1+$C$10) -> 2.5797834e+09 | K26: =J26*(1+$C$10) -> 2.6571769e+09 | L26: =K26*(1+$C$10) -> 2.7368922e+09
A27: Vacancy Loss | C27: =C26*(1-$C$14) -> 3.1464e+08 | D27: =D26*(1-$C$15) -> 864211200 | E27: =E26*(1-$C$15) -> 890137536 | F27: =F26*(1-$C$15) -> 9.1684166e+08 | G27: =G26*(1-$C$15) -> 9.4434691e+08 | H27: =H26*(1-$C$15) -> 9.7267732e+08 | I27: =I26*(1-$C$15) -> 1.0018576e+09 | J27: =J26*(1-$C$15) -> 1.0319134e+09 | K27: =K26*(1-$C$15) -> 1.0628708e+09 | L27: =L26*(1-$C$15) -> 1.0947569e+09
A28: Total Revenue | C28: =C26-C27 -> 1782960000 | D28: =D26-D27 -> 1296316800 | E28: =E26-E27 -> 1335206304 | F28: =F26-F27 -> 1.3752625e+09 | G28: =G26-G27 -> 1.4165204e+09 | H28: =H26-H27 -> 1.459016e+09 | I28: =I26-I27 -> 1.5027865e+09 | J28: =J26-J27 -> 1.5478701e+09 | ... L28: =L26-L27 -> 1.6421353e+09
A29: Deductions
A30: Cove Platform Fee | C30: =-C28*$C$18 -> -44574000 | D30: =-D28*$C$18 -> -32407920 | E30: =-E28*$C$18 -> -33380158 | F30: =-F28*$C$18 -> -34381562 | G30: =-G28*$C$18 -> -35413009 | H30: =-H28*$C$18 -> -36475399 | I30: =-I28*$C$18 -> -37569661 | J30: =-J28*$C$18 -> -38696751 | ... L30: =-L28*$C$18 -> -41053383
A31: OTA Cost | C31: =-C28*$C$19 -> -165815280 | D31: =-D28*$C$19 -> -1.2055746e+08 | E31: =-E28*$C$19 -> -1.2417419e+08 | F31: =-F28*$C$19 -> -1.2789941e+08 | G31: =-G28*$C$19 -> -1.3173639e+08 | H31: =-H28*$C$19 -> -1.3568849e+08 | I31: =-I28*$C$19 -> -1.3975914e+08 | J31: =-J28*$C$19 -> -1.4395191e+08 | ... L31: =-L28*$C$19 -> -1.5271859e+08
A32: Net Revenue | C32: =SUM(C28:C31) -> 1572570720 | D32: =SUM(D28:D31) -> 1.1433514e+09 | E32: =SUM(E28:E31) -> 1.177652e+09 | F32: =SUM(F28:F31) -> 1.2129815e+09 | G32: =SUM(G28:G31) -> 1.249371e+09 | H32: =SUM(H28:H31) -> 1.2868521e+09 | I32: =SUM(I28:I31) -> 1.3254577e+09 | J32: =SUM(J28:J31) -> 1.3652214e+09 | ... L32: =SUM(L28:L31) -> 1.4483634e+09
A33: Operating Expenses (OPEX) | C33: =-C28*$C$20 -> -527756160 | D33: =C33*(1+$C$11) -> -540950064 | E33: =D33*(1+$C$11) -> -5.5447382e+08 | F33: =E33*(1+$C$11) -> -5.6833566e+08 | G33: =F33*(1+$C$11) -> -5.8254405e+08 | H33: =G33*(1+$C$11) -> -5.9710765e+08 | I33: =H33*(1+$C$11) -> -6.1203535e+08 | J33: =I33*(1+$C$11) -> -6.2733623e+08 | K33: =J33*(1+$C$11) -> -6.4301963e+08 | L33: =K33*(1+$C$11) -> -6.5909513e+08
A34: Gross Operating Profit (GOP) | C34: =SUM(C32:C33) -> 1044814560 | D34: =SUM(D32:D33) -> 6.0240135e+08 | E34: =SUM(E32:E33) -> 6.2317814e+08 | F34: =SUM(F32:F33) -> 6.4464586e+08 | G34: =SUM(G32:G33) -> 6.6682691e+08 | H34: =SUM(H32:H33) -> 6.8974444e+08 | I34: =SUM(I32:I33) -> 7.1342231e+08 | J34: =SUM(J32:J33) -> 7.3788516e+08 | ... L34: =SUM(L32:L33) -> 7.8926824e+08
A35: Cove Incentive Fee | C35: =-C34*$C$21 -> -1.8806662e+08 | D35: =-D34*$C$21 -> -1.0843224e+08 | E35: =-E34*$C$21 -> -1.1217207e+08 | F35: =-F34*$C$21 -> -1.1603625e+08 | G35: =-G34*$C$21 -> -1.2002884e+08 | H35: =-H34*$C$21 -> -1.24154e+08 | I35: =-I34*$C$21 -> -1.2841602e+08 | J35: =-J34*$C$21 -> -1.3281933e+08 | ... L35: =-L34*$C$21 -> -1.4206828e+08
A36: Owner Share (NOI) | C36: =SUM(C34:C35) -> 8.5674794e+08 | D36: =SUM(D34:D35) -> 4.9396911e+08 | E36: =SUM(E34:E35) -> 5.1100608e+08 | F36: =SUM(F34:F35) -> 5.286096e+08 | G36: =SUM(G34:G35) -> 5.4679807e+08 | H36: =SUM(H34:H35) -> 5.6559044e+08 | I36: =SUM(I34:I35) -> 5.850063e+08 | J36: =SUM(J34:J35) -> 6.0506583e+08 | ... L36: =SUM(L34:L35) -> 6.4719996e+08
A37: Project Cash Flow | B37: =-$C$3 -> -7000000000 | C37: =C36 -> 8.5674794e+08 | D37: =D36 -> 4.9396911e+08 | E37: =E36 -> 5.1100608e+08 | F37: =F36 -> 5.286096e+08 | G37: =G36 -> 5.4679807e+08 | H37: =H36 -> 5.6559044e+08 | I37: =I36 -> 5.850063e+08 | J37: =J36 -> 6.0506583e+08 | ... L37: =L36 -> 6.4719996e+08
A38: Cumulative Cash Flow | B38: =B37 -> -7000000000 | C38: =B38+C37 -> -6.1432521e+09 | D38: =C38+D37 -> -5.649283e+09 | E38: =D38+E37 -> -5.1382769e+09 | F38: =E38+F37 -> -4.6096673e+09 | G38: =F38+G37 -> -4.0628692e+09 | H38: =G38+H37 -> -3.4972788e+09 | I38: =H38+I37 -> -2.9122725e+09 | J38: =I38+J37 -> -2.3072066e+09 | ... L38: =K38+L37 -> -1.0342168e+09
A40: Cash Flow for IRR | B40: =-$C$3 -> -7000000000 | J40: Occupancy Break-Even
A41: Year 1 | B41: =C37 -> 8.5674794e+08 | J41: Break even no of rooms | K41: =-((D30+D31+D33+D35)/12)/C7 -> 14.535284
A42: Year 2 | B42: =D$37 -> 4.9396911e+08 | J42: Break even occupancy % | K42: =K41/C6 -> 0.38250748
A43: Year 3 | B43: =E$37 -> 5.1100608e+08 | J43: We need to rent 18 rooms in order to cover all the monthly costs
A44: Year 4 | B44: =F$37 -> 5.286096e+08
A45: Year 5 | B45: =G$37 -> 5.4679807e+08
A46: Year 6 | B46: =H$37 -> 5.6559044e+08
A47: Year 7 | B47: =I$37 -> 5.850063e+08
...

Sheet Financial Model lower monthly
A1: Project Assumptions | C1: Values
A2: Investment
A3: Initial Investment (Landlord) | C3: 7700000000
A5: Operations
A6: Number of Rooms | C6: 38
A7: Average Monthly Rent per Room | C7: 4600000
A9: Growth & Inflation
A10: Annual Rent Growth | C10: 0.03
A11: Annual OPEX Growth | C11: 0.025
A13: Occupancy Ramp-Up
A14: Year 1 Occupancy | C14: 0.85
A15: Stabilized Occupancy (Y2+) | C15: 0.92
A17: Fees & Costs (% of Total Revenue)
A18: Cove Platform Fee | C18: 0.025
A19: OTA Cost | C19: 0.093
A20: OPEX (% of Net Revenue) | C20: 0.296
A21: Cove Incentive Fee (% of GOP) | C21: 0.18
A24: Line Item | B24: Year 0 | C24: Year 1 | D24: Year 2 | E24: Year 3 | F24: Year 4 | G24: Year 5 | H24: Year 6 | I24: Year 7 | J24: Year 8 | K24: Year 9 | L24: Year 10
A25: Revenue
A26: Gross Potential Rent | C26: =$C$6*$C$7*12 -> 2097600000 | D26: =C26*(1+$C$10) -> 2160528000 | E26: =D26*(1+$C$10) -> 2225343840 | F26: =E26*(1+$C$10) -> 2.2921042e+09 | G26: =F26*(1+$C$10) -> 2.3608673e+09 | H26: =G26*(1+$C$10) -> 2.4316933e+09 | I26: =H26*(1+$C$10) -> 2.5046441e+09 | J26: =I26*(1+$C$10) -> 2.5797834e+09 | K26: =J26*(1+$C$10) -> 2.6571769e+09 | L26: =K26*(1+$C$10) -> 2.7368922e+09
A27: Vacancy Loss | C27: =C26*(1-$C$14) -> 3.1464e+08 | D27: =D26*(1-$C$15) -> 1.7284224e+08 | E27: =E26*(1-$C$15) -> 1.7802751e+08 | F27: =F26*(1-$C$15) -> 1.8336833e+08 | G27: =G26*(1-$C$15) -> 1.8886938e+08 | H27: =H26*(1-$C$15) -> 1.9453546e+08 | I27: =I26*(1-$C$15) -> 2.0037153e+08 | J27: =J26*(1-$C$15) -> 2.0638267e+08 | K27: =K26*(1-$C$15) -> 2.1257415e+08 | L27: =L26*(1-$C$15) -> 2.1895138e+08
A28: Total Revenue | C28: =C26-C27 -> 1782960000 | D28: =D26-D27 -> 1987685760 | E28: =E26-E27 -> 2.0473163e+09 | F28: =F26-F27 -> 2.1087358e+09 | G28: =G26-G27 -> 2.1719979e+09 | H28: =H26-H27 -> 2.2371578e+09 | I28: =I26-I27 -> 2.3042726e+09 | J28: =J26-J27 -> 2.3734007e+09 | ... L28: =L26-L27 -> 2.5179409e+09
A29: Deductions
A30: Cove Platform Fee | C30: =-C28*$C$18 -> -44574000 | D30: =-D28*$C$18 -> -49692144 | E30: =-E28*$C$18 -> -51182908 | F30: =-F28*$C$18 -> -52718396 | G30: =-G28*$C$18 -> -54299947 | H30: =-H28*$C$18 -> -55928946 | I30: =-I28*$C$18 -> -57606814 | J30: =-J28*$C$18 -> -59335019 | ... L30: =-L28*$C$18 -> -62948521
A31: OTA Cost | C31: =-C28*$C$19 -> -165815280 | D31: =-D28*$C$19 -> -1.8485478e+08 | E31: =-E28*$C$19 -> -1.9040042e+08 | F31: =-F28*$C$19 -> -1.9611243e+08 | G31: =-G28*$C$19 -> -2.019958e+08 | H31: =-H28*$C$19 -> -2.0805568e+08 | I31: =-I28*$C$19 -> -2.1429735e+08 | J31: =-J28*$C$19 -> -2.2072627e+08 | ... L31: =-L28*$C$19 -> -2.341685e+08
